INFO:uvicorn.error:Started server process [4624]
INFO:uvicorn.error:Waiting for application startup.
INFO:uvicorn.error:Application startup complete.
CRITICAL:root:Store name already exists
CRITICAL:root:Store name already exists
CRITICAL:root:Store name already exists
CRITICAL:root:product name already exist
CRITICAL:root:product name already exist
CRITICAL:root:product name already exist
CRITICAL:root:product name already exist
CRITICAL:root:product name already exist
CRITICAL:root:product name already exist
CRITICAL:root:product does not exist
CRITICAL:root:product does not exist
CRITICAL:root:product does not exist
CRITICAL:root:product does not exist
CRITICAL:root:product does not exist
CRITICAL:root:product does not exist
CRITICAL:root:product does not exist
CRITICAL:root:product does not exist
CRITICAL:root:product does not exist
CRITICAL:root:product does not exist
CRITICAL:root:product does not exist
CRITICAL:root:product does not exist
INFO:uvicorn.error:Started server process [1616]
INFO:uvicorn.error:Waiting for application startup.
INFO:uvicorn.error:Application startup complete.
INFO:uvicorn.error:Started server process [4716]
INFO:uvicorn.error:Waiting for application startup.
INFO:uvicorn.error:Application startup complete.
INFO:uvicorn.error:Started server process [16820]
INFO:uvicorn.error:Waiting for application startup.
INFO:uvicorn.error:Application startup complete.
INFO:uvicorn.error:Started server process [15552]
INFO:uvicorn.error:Waiting for application startup.
INFO:uvicorn.error:Application startup complete.
INFO:uvicorn.error:Started server process [22944]
INFO:uvicorn.error:Waiting for application startup.
INFO:uvicorn.error:Application startup complete.
INFO:uvicorn.error:Started server process [25256]
INFO:uvicorn.error:Waiting for application startup.
INFO:uvicorn.error:Application startup complete.
INFO:uvicorn.error:Started server process [11720]
INFO:uvicorn.error:Waiting for application startup.
INFO:uvicorn.error:Application startup complete.
CRITICAL:root:Store id does not exist or is inactive
CRITICAL:root:Store id does not exist or is inactive
CRITICAL:root:Store id does not exist or is inactive
CRITICAL:root:Store id does not exist or is inactive
INFO:uvicorn.error:Started server process [10096]
INFO:uvicorn.error:Waiting for application startup.
INFO:uvicorn.error:Application startup complete.
INFO:uvicorn.error:Started server process [18452]
INFO:uvicorn.error:Waiting for application startup.
INFO:uvicorn.error:Application startup complete.
INFO:uvicorn.error:Started server process [25340]
INFO:uvicorn.error:Waiting for application startup.
INFO:uvicorn.error:Application startup complete.
INFO:uvicorn.error:Started server process [21544]
INFO:uvicorn.error:Waiting for application startup.
INFO:uvicorn.error:Application startup complete.
INFO:uvicorn.error:Started server process [23060]
INFO:uvicorn.error:Waiting for application startup.
INFO:uvicorn.error:Application startup complete.
INFO:uvicorn.error:Started server process [12584]
INFO:uvicorn.error:Waiting for application startup.
INFO:uvicorn.error:Application startup complete.
CRITICAL:root:username already exists
CRITICAL:root:username already exists
ERROR:uvicorn.error:Exception in ASGI application
Traceback (most recent call last):
  File "C:\Users\tomer\AppData\Local\Programs\Python\Python310\lib\site-packages\uvicorn\protocols\http\httptools_impl.py", line 372, in run_asgi
    result = await app(self.scope, self.receive, self.send)
  File "C:\Users\tomer\AppData\Local\Programs\Python\Python310\lib\site-packages\uvicorn\middleware\proxy_headers.py", line 75, in __call__
    return await self.app(scope, receive, send)
  File "C:\Users\tomer\AppData\Local\Programs\Python\Python310\lib\site-packages\fastapi\applications.py", line 261, in __call__
    await super().__call__(scope, receive, send)
  File "C:\Users\tomer\AppData\Local\Programs\Python\Python310\lib\site-packages\starlette\applications.py", line 112, in __call__
    await self.middleware_stack(scope, receive, send)
  File "C:\Users\tomer\AppData\Local\Programs\Python\Python310\lib\site-packages\starlette\middleware\errors.py", line 181, in __call__
    raise exc
  File "C:\Users\tomer\AppData\Local\Programs\Python\Python310\lib\site-packages\starlette\middleware\errors.py", line 159, in __call__
    await self.app(scope, receive, _send)
  File "C:\Users\tomer\AppData\Local\Programs\Python\Python310\lib\site-packages\starlette\middleware\cors.py", line 92, in __call__
    await self.simple_response(scope, receive, send, request_headers=headers)
  File "C:\Users\tomer\AppData\Local\Programs\Python\Python310\lib\site-packages\starlette\middleware\cors.py", line 147, in simple_response
    await self.app(scope, receive, send)
  File "C:\Users\tomer\AppData\Local\Programs\Python\Python310\lib\site-packages\starlette\exceptions.py", line 82, in __call__
    raise exc
  File "C:\Users\tomer\AppData\Local\Programs\Python\Python310\lib\site-packages\starlette\exceptions.py", line 71, in __call__
    await self.app(scope, receive, sender)
  File "C:\Users\tomer\AppData\Local\Programs\Python\Python310\lib\site-packages\fastapi\middleware\asyncexitstack.py", line 21, in __call__
    raise e
  File "C:\Users\tomer\AppData\Local\Programs\Python\Python310\lib\site-packages\fastapi\middleware\asyncexitstack.py", line 18, in __call__
    await self.app(scope, receive, send)
  File "C:\Users\tomer\AppData\Local\Programs\Python\Python310\lib\site-packages\starlette\routing.py", line 656, in __call__
    await route.handle(scope, receive, send)
  File "C:\Users\tomer\AppData\Local\Programs\Python\Python310\lib\site-packages\starlette\routing.py", line 259, in handle
    await self.app(scope, receive, send)
  File "C:\Users\tomer\AppData\Local\Programs\Python\Python310\lib\site-packages\starlette\routing.py", line 61, in app
    response = await func(request)
  File "C:\Users\tomer\AppData\Local\Programs\Python\Python310\lib\site-packages\fastapi\routing.py", line 227, in app
    raw_response = await run_endpoint_function(
  File "C:\Users\tomer\AppData\Local\Programs\Python\Python310\lib\site-packages\fastapi\routing.py", line 162, in run_endpoint_function
    return await run_in_threadpool(dependant.call, **values)
  File "C:\Users\tomer\AppData\Local\Programs\Python\Python310\lib\site-packages\starlette\concurrency.py", line 39, in run_in_threadpool
    return await anyio.to_thread.run_sync(func, *args)
  File "C:\Users\tomer\AppData\Local\Programs\Python\Python310\lib\site-packages\anyio\to_thread.py", line 28, in run_sync
    return await get_asynclib().run_sync_in_worker_thread(func, *args, cancellable=cancellable,
  File "C:\Users\tomer\AppData\Local\Programs\Python\Python310\lib\site-packages\anyio\_backends\_asyncio.py", line 818, in run_sync_in_worker_thread
    return await future
  File "C:\Users\tomer\AppData\Local\Programs\Python\Python310\lib\site-packages\anyio\_backends\_asyncio.py", line 754, in run
    result = context.run(func, *args)
  File "C:\Users\tomer\Desktop\sadna\Workshop\.\Code\Backend\Server-FastAPI\Server.py", line 153, in register
    res = service.register(user_info.id, user_info_dict)
  File "C:\Users\tomer\Desktop\sadna\Workshop\.\Code\Backend\Service\Service.py", line 137, in register
    response = Response(self.facade.register(guest_id, user_info))
  File "C:\Users\tomer\Desktop\sadna\Workshop\.\Code\Backend\Domain\Facade.py", line 103, in register
    return self.user_controller.register(guest_id, user_info)
  File "C:\Users\tomer\Desktop\sadna\Workshop\.\Code\Backend\Domain\Controllers\UserController.py", line 40, in register
    new_status = self.__users[user_id].register(member_info)
KeyError: ''
ERROR:uvicorn.error:Exception in ASGI application
Traceback (most recent call last):
  File "C:\Users\tomer\AppData\Local\Programs\Python\Python310\lib\site-packages\uvicorn\protocols\http\httptools_impl.py", line 372, in run_asgi
    result = await app(self.scope, self.receive, self.send)
  File "C:\Users\tomer\AppData\Local\Programs\Python\Python310\lib\site-packages\uvicorn\middleware\proxy_headers.py", line 75, in __call__
    return await self.app(scope, receive, send)
  File "C:\Users\tomer\AppData\Local\Programs\Python\Python310\lib\site-packages\fastapi\applications.py", line 261, in __call__
    await super().__call__(scope, receive, send)
  File "C:\Users\tomer\AppData\Local\Programs\Python\Python310\lib\site-packages\starlette\applications.py", line 112, in __call__
    await self.middleware_stack(scope, receive, send)
  File "C:\Users\tomer\AppData\Local\Programs\Python\Python310\lib\site-packages\starlette\middleware\errors.py", line 181, in __call__
    raise exc
  File "C:\Users\tomer\AppData\Local\Programs\Python\Python310\lib\site-packages\starlette\middleware\errors.py", line 159, in __call__
    await self.app(scope, receive, _send)
  File "C:\Users\tomer\AppData\Local\Programs\Python\Python310\lib\site-packages\starlette\middleware\cors.py", line 92, in __call__
    await self.simple_response(scope, receive, send, request_headers=headers)
  File "C:\Users\tomer\AppData\Local\Programs\Python\Python310\lib\site-packages\starlette\middleware\cors.py", line 147, in simple_response
    await self.app(scope, receive, send)
  File "C:\Users\tomer\AppData\Local\Programs\Python\Python310\lib\site-packages\starlette\exceptions.py", line 82, in __call__
    raise exc
  File "C:\Users\tomer\AppData\Local\Programs\Python\Python310\lib\site-packages\starlette\exceptions.py", line 71, in __call__
    await self.app(scope, receive, sender)
  File "C:\Users\tomer\AppData\Local\Programs\Python\Python310\lib\site-packages\fastapi\middleware\asyncexitstack.py", line 21, in __call__
    raise e
  File "C:\Users\tomer\AppData\Local\Programs\Python\Python310\lib\site-packages\fastapi\middleware\asyncexitstack.py", line 18, in __call__
    await self.app(scope, receive, send)
  File "C:\Users\tomer\AppData\Local\Programs\Python\Python310\lib\site-packages\starlette\routing.py", line 656, in __call__
    await route.handle(scope, receive, send)
  File "C:\Users\tomer\AppData\Local\Programs\Python\Python310\lib\site-packages\starlette\routing.py", line 259, in handle
    await self.app(scope, receive, send)
  File "C:\Users\tomer\AppData\Local\Programs\Python\Python310\lib\site-packages\starlette\routing.py", line 61, in app
    response = await func(request)
  File "C:\Users\tomer\AppData\Local\Programs\Python\Python310\lib\site-packages\fastapi\routing.py", line 227, in app
    raw_response = await run_endpoint_function(
  File "C:\Users\tomer\AppData\Local\Programs\Python\Python310\lib\site-packages\fastapi\routing.py", line 162, in run_endpoint_function
    return await run_in_threadpool(dependant.call, **values)
  File "C:\Users\tomer\AppData\Local\Programs\Python\Python310\lib\site-packages\starlette\concurrency.py", line 39, in run_in_threadpool
    return await anyio.to_thread.run_sync(func, *args)
  File "C:\Users\tomer\AppData\Local\Programs\Python\Python310\lib\site-packages\anyio\to_thread.py", line 28, in run_sync
    return await get_asynclib().run_sync_in_worker_thread(func, *args, cancellable=cancellable,
  File "C:\Users\tomer\AppData\Local\Programs\Python\Python310\lib\site-packages\anyio\_backends\_asyncio.py", line 818, in run_sync_in_worker_thread
    return await future
  File "C:\Users\tomer\AppData\Local\Programs\Python\Python310\lib\site-packages\anyio\_backends\_asyncio.py", line 754, in run
    result = context.run(func, *args)
  File "C:\Users\tomer\Desktop\sadna\Workshop\.\Code\Backend\Server-FastAPI\Server.py", line 153, in register
    res = service.register(user_info.id, user_info_dict)
  File "C:\Users\tomer\Desktop\sadna\Workshop\.\Code\Backend\Service\Service.py", line 137, in register
    response = Response(self.facade.register(guest_id, user_info))
  File "C:\Users\tomer\Desktop\sadna\Workshop\.\Code\Backend\Domain\Facade.py", line 103, in register
    return self.user_controller.register(guest_id, user_info)
  File "C:\Users\tomer\Desktop\sadna\Workshop\.\Code\Backend\Domain\Controllers\UserController.py", line 40, in register
    new_status = self.__users[user_id].register(member_info)
KeyError: ''
ERROR:uvicorn.error:Exception in ASGI application
Traceback (most recent call last):
  File "C:\Users\tomer\AppData\Local\Programs\Python\Python310\lib\site-packages\uvicorn\protocols\http\httptools_impl.py", line 372, in run_asgi
    result = await app(self.scope, self.receive, self.send)
  File "C:\Users\tomer\AppData\Local\Programs\Python\Python310\lib\site-packages\uvicorn\middleware\proxy_headers.py", line 75, in __call__
    return await self.app(scope, receive, send)
  File "C:\Users\tomer\AppData\Local\Programs\Python\Python310\lib\site-packages\fastapi\applications.py", line 261, in __call__
    await super().__call__(scope, receive, send)
  File "C:\Users\tomer\AppData\Local\Programs\Python\Python310\lib\site-packages\starlette\applications.py", line 112, in __call__
    await self.middleware_stack(scope, receive, send)
  File "C:\Users\tomer\AppData\Local\Programs\Python\Python310\lib\site-packages\starlette\middleware\errors.py", line 181, in __call__
    raise exc
  File "C:\Users\tomer\AppData\Local\Programs\Python\Python310\lib\site-packages\starlette\middleware\errors.py", line 159, in __call__
    await self.app(scope, receive, _send)
  File "C:\Users\tomer\AppData\Local\Programs\Python\Python310\lib\site-packages\starlette\middleware\cors.py", line 92, in __call__
    await self.simple_response(scope, receive, send, request_headers=headers)
  File "C:\Users\tomer\AppData\Local\Programs\Python\Python310\lib\site-packages\starlette\middleware\cors.py", line 147, in simple_response
    await self.app(scope, receive, send)
  File "C:\Users\tomer\AppData\Local\Programs\Python\Python310\lib\site-packages\starlette\exceptions.py", line 82, in __call__
    raise exc
  File "C:\Users\tomer\AppData\Local\Programs\Python\Python310\lib\site-packages\starlette\exceptions.py", line 71, in __call__
    await self.app(scope, receive, sender)
  File "C:\Users\tomer\AppData\Local\Programs\Python\Python310\lib\site-packages\fastapi\middleware\asyncexitstack.py", line 21, in __call__
    raise e
  File "C:\Users\tomer\AppData\Local\Programs\Python\Python310\lib\site-packages\fastapi\middleware\asyncexitstack.py", line 18, in __call__
    await self.app(scope, receive, send)
  File "C:\Users\tomer\AppData\Local\Programs\Python\Python310\lib\site-packages\starlette\routing.py", line 656, in __call__
    await route.handle(scope, receive, send)
  File "C:\Users\tomer\AppData\Local\Programs\Python\Python310\lib\site-packages\starlette\routing.py", line 259, in handle
    await self.app(scope, receive, send)
  File "C:\Users\tomer\AppData\Local\Programs\Python\Python310\lib\site-packages\starlette\routing.py", line 61, in app
    response = await func(request)
  File "C:\Users\tomer\AppData\Local\Programs\Python\Python310\lib\site-packages\fastapi\routing.py", line 227, in app
    raw_response = await run_endpoint_function(
  File "C:\Users\tomer\AppData\Local\Programs\Python\Python310\lib\site-packages\fastapi\routing.py", line 162, in run_endpoint_function
    return await run_in_threadpool(dependant.call, **values)
  File "C:\Users\tomer\AppData\Local\Programs\Python\Python310\lib\site-packages\starlette\concurrency.py", line 39, in run_in_threadpool
    return await anyio.to_thread.run_sync(func, *args)
  File "C:\Users\tomer\AppData\Local\Programs\Python\Python310\lib\site-packages\anyio\to_thread.py", line 28, in run_sync
    return await get_asynclib().run_sync_in_worker_thread(func, *args, cancellable=cancellable,
  File "C:\Users\tomer\AppData\Local\Programs\Python\Python310\lib\site-packages\anyio\_backends\_asyncio.py", line 818, in run_sync_in_worker_thread
    return await future
  File "C:\Users\tomer\AppData\Local\Programs\Python\Python310\lib\site-packages\anyio\_backends\_asyncio.py", line 754, in run
    result = context.run(func, *args)
  File "C:\Users\tomer\Desktop\sadna\Workshop\.\Code\Backend\Server-FastAPI\Server.py", line 153, in register
    res = service.register(user_info.id, user_info_dict)
  File "C:\Users\tomer\Desktop\sadna\Workshop\.\Code\Backend\Service\Service.py", line 137, in register
    response = Response(self.facade.register(guest_id, user_info))
  File "C:\Users\tomer\Desktop\sadna\Workshop\.\Code\Backend\Domain\Facade.py", line 103, in register
    return self.user_controller.register(guest_id, user_info)
  File "C:\Users\tomer\Desktop\sadna\Workshop\.\Code\Backend\Domain\Controllers\UserController.py", line 40, in register
    new_status = self.__users[user_id].register(member_info)
KeyError: ''
ERROR:uvicorn.error:Exception in ASGI application
Traceback (most recent call last):
  File "C:\Users\tomer\AppData\Local\Programs\Python\Python310\lib\site-packages\uvicorn\protocols\http\httptools_impl.py", line 372, in run_asgi
    result = await app(self.scope, self.receive, self.send)
  File "C:\Users\tomer\AppData\Local\Programs\Python\Python310\lib\site-packages\uvicorn\middleware\proxy_headers.py", line 75, in __call__
    return await self.app(scope, receive, send)
  File "C:\Users\tomer\AppData\Local\Programs\Python\Python310\lib\site-packages\fastapi\applications.py", line 261, in __call__
    await super().__call__(scope, receive, send)
  File "C:\Users\tomer\AppData\Local\Programs\Python\Python310\lib\site-packages\starlette\applications.py", line 112, in __call__
    await self.middleware_stack(scope, receive, send)
  File "C:\Users\tomer\AppData\Local\Programs\Python\Python310\lib\site-packages\starlette\middleware\errors.py", line 181, in __call__
    raise exc
  File "C:\Users\tomer\AppData\Local\Programs\Python\Python310\lib\site-packages\starlette\middleware\errors.py", line 159, in __call__
    await self.app(scope, receive, _send)
  File "C:\Users\tomer\AppData\Local\Programs\Python\Python310\lib\site-packages\starlette\middleware\cors.py", line 92, in __call__
    await self.simple_response(scope, receive, send, request_headers=headers)
  File "C:\Users\tomer\AppData\Local\Programs\Python\Python310\lib\site-packages\starlette\middleware\cors.py", line 147, in simple_response
    await self.app(scope, receive, send)
  File "C:\Users\tomer\AppData\Local\Programs\Python\Python310\lib\site-packages\starlette\exceptions.py", line 82, in __call__
    raise exc
  File "C:\Users\tomer\AppData\Local\Programs\Python\Python310\lib\site-packages\starlette\exceptions.py", line 71, in __call__
    await self.app(scope, receive, sender)
  File "C:\Users\tomer\AppData\Local\Programs\Python\Python310\lib\site-packages\fastapi\middleware\asyncexitstack.py", line 21, in __call__
    raise e
  File "C:\Users\tomer\AppData\Local\Programs\Python\Python310\lib\site-packages\fastapi\middleware\asyncexitstack.py", line 18, in __call__
    await self.app(scope, receive, send)
  File "C:\Users\tomer\AppData\Local\Programs\Python\Python310\lib\site-packages\starlette\routing.py", line 656, in __call__
    await route.handle(scope, receive, send)
  File "C:\Users\tomer\AppData\Local\Programs\Python\Python310\lib\site-packages\starlette\routing.py", line 259, in handle
    await self.app(scope, receive, send)
  File "C:\Users\tomer\AppData\Local\Programs\Python\Python310\lib\site-packages\starlette\routing.py", line 61, in app
    response = await func(request)
  File "C:\Users\tomer\AppData\Local\Programs\Python\Python310\lib\site-packages\fastapi\routing.py", line 227, in app
    raw_response = await run_endpoint_function(
  File "C:\Users\tomer\AppData\Local\Programs\Python\Python310\lib\site-packages\fastapi\routing.py", line 162, in run_endpoint_function
    return await run_in_threadpool(dependant.call, **values)
  File "C:\Users\tomer\AppData\Local\Programs\Python\Python310\lib\site-packages\starlette\concurrency.py", line 39, in run_in_threadpool
    return await anyio.to_thread.run_sync(func, *args)
  File "C:\Users\tomer\AppData\Local\Programs\Python\Python310\lib\site-packages\anyio\to_thread.py", line 28, in run_sync
    return await get_asynclib().run_sync_in_worker_thread(func, *args, cancellable=cancellable,
  File "C:\Users\tomer\AppData\Local\Programs\Python\Python310\lib\site-packages\anyio\_backends\_asyncio.py", line 818, in run_sync_in_worker_thread
    return await future
  File "C:\Users\tomer\AppData\Local\Programs\Python\Python310\lib\site-packages\anyio\_backends\_asyncio.py", line 754, in run
    result = context.run(func, *args)
  File "C:\Users\tomer\Desktop\sadna\Workshop\.\Code\Backend\Server-FastAPI\Server.py", line 153, in register
    res = service.register(user_info.id, user_info_dict)
  File "C:\Users\tomer\Desktop\sadna\Workshop\.\Code\Backend\Service\Service.py", line 137, in register
    response = Response(self.facade.register(guest_id, user_info))
  File "C:\Users\tomer\Desktop\sadna\Workshop\.\Code\Backend\Domain\Facade.py", line 103, in register
    return self.user_controller.register(guest_id, user_info)
  File "C:\Users\tomer\Desktop\sadna\Workshop\.\Code\Backend\Domain\Controllers\UserController.py", line 40, in register
    new_status = self.__users[user_id].register(member_info)
KeyError: ''
ERROR:uvicorn.error:Exception in ASGI application
Traceback (most recent call last):
  File "C:\Users\tomer\AppData\Local\Programs\Python\Python310\lib\site-packages\uvicorn\protocols\http\httptools_impl.py", line 372, in run_asgi
    result = await app(self.scope, self.receive, self.send)
  File "C:\Users\tomer\AppData\Local\Programs\Python\Python310\lib\site-packages\uvicorn\middleware\proxy_headers.py", line 75, in __call__
    return await self.app(scope, receive, send)
  File "C:\Users\tomer\AppData\Local\Programs\Python\Python310\lib\site-packages\fastapi\applications.py", line 261, in __call__
    await super().__call__(scope, receive, send)
  File "C:\Users\tomer\AppData\Local\Programs\Python\Python310\lib\site-packages\starlette\applications.py", line 112, in __call__
    await self.middleware_stack(scope, receive, send)
  File "C:\Users\tomer\AppData\Local\Programs\Python\Python310\lib\site-packages\starlette\middleware\errors.py", line 181, in __call__
    raise exc
  File "C:\Users\tomer\AppData\Local\Programs\Python\Python310\lib\site-packages\starlette\middleware\errors.py", line 159, in __call__
    await self.app(scope, receive, _send)
  File "C:\Users\tomer\AppData\Local\Programs\Python\Python310\lib\site-packages\starlette\middleware\cors.py", line 92, in __call__
    await self.simple_response(scope, receive, send, request_headers=headers)
  File "C:\Users\tomer\AppData\Local\Programs\Python\Python310\lib\site-packages\starlette\middleware\cors.py", line 147, in simple_response
    await self.app(scope, receive, send)
  File "C:\Users\tomer\AppData\Local\Programs\Python\Python310\lib\site-packages\starlette\exceptions.py", line 82, in __call__
    raise exc
  File "C:\Users\tomer\AppData\Local\Programs\Python\Python310\lib\site-packages\starlette\exceptions.py", line 71, in __call__
    await self.app(scope, receive, sender)
  File "C:\Users\tomer\AppData\Local\Programs\Python\Python310\lib\site-packages\fastapi\middleware\asyncexitstack.py", line 21, in __call__
    raise e
  File "C:\Users\tomer\AppData\Local\Programs\Python\Python310\lib\site-packages\fastapi\middleware\asyncexitstack.py", line 18, in __call__
    await self.app(scope, receive, send)
  File "C:\Users\tomer\AppData\Local\Programs\Python\Python310\lib\site-packages\starlette\routing.py", line 656, in __call__
    await route.handle(scope, receive, send)
  File "C:\Users\tomer\AppData\Local\Programs\Python\Python310\lib\site-packages\starlette\routing.py", line 259, in handle
    await self.app(scope, receive, send)
  File "C:\Users\tomer\AppData\Local\Programs\Python\Python310\lib\site-packages\starlette\routing.py", line 61, in app
    response = await func(request)
  File "C:\Users\tomer\AppData\Local\Programs\Python\Python310\lib\site-packages\fastapi\routing.py", line 227, in app
    raw_response = await run_endpoint_function(
  File "C:\Users\tomer\AppData\Local\Programs\Python\Python310\lib\site-packages\fastapi\routing.py", line 162, in run_endpoint_function
    return await run_in_threadpool(dependant.call, **values)
  File "C:\Users\tomer\AppData\Local\Programs\Python\Python310\lib\site-packages\starlette\concurrency.py", line 39, in run_in_threadpool
    return await anyio.to_thread.run_sync(func, *args)
  File "C:\Users\tomer\AppData\Local\Programs\Python\Python310\lib\site-packages\anyio\to_thread.py", line 28, in run_sync
    return await get_asynclib().run_sync_in_worker_thread(func, *args, cancellable=cancellable,
  File "C:\Users\tomer\AppData\Local\Programs\Python\Python310\lib\site-packages\anyio\_backends\_asyncio.py", line 818, in run_sync_in_worker_thread
    return await future
  File "C:\Users\tomer\AppData\Local\Programs\Python\Python310\lib\site-packages\anyio\_backends\_asyncio.py", line 754, in run
    result = context.run(func, *args)
  File "C:\Users\tomer\Desktop\sadna\Workshop\.\Code\Backend\Server-FastAPI\Server.py", line 153, in register
    res = service.register(user_info.id, user_info_dict)
  File "C:\Users\tomer\Desktop\sadna\Workshop\.\Code\Backend\Service\Service.py", line 137, in register
    response = Response(self.facade.register(guest_id, user_info))
  File "C:\Users\tomer\Desktop\sadna\Workshop\.\Code\Backend\Domain\Facade.py", line 103, in register
    return self.user_controller.register(guest_id, user_info)
  File "C:\Users\tomer\Desktop\sadna\Workshop\.\Code\Backend\Domain\Controllers\UserController.py", line 40, in register
    new_status = self.__users[user_id].register(member_info)
KeyError: ''
ERROR:uvicorn.error:Exception in ASGI application
Traceback (most recent call last):
  File "C:\Users\tomer\AppData\Local\Programs\Python\Python310\lib\site-packages\uvicorn\protocols\http\httptools_impl.py", line 372, in run_asgi
    result = await app(self.scope, self.receive, self.send)
  File "C:\Users\tomer\AppData\Local\Programs\Python\Python310\lib\site-packages\uvicorn\middleware\proxy_headers.py", line 75, in __call__
    return await self.app(scope, receive, send)
  File "C:\Users\tomer\AppData\Local\Programs\Python\Python310\lib\site-packages\fastapi\applications.py", line 261, in __call__
    await super().__call__(scope, receive, send)
  File "C:\Users\tomer\AppData\Local\Programs\Python\Python310\lib\site-packages\starlette\applications.py", line 112, in __call__
    await self.middleware_stack(scope, receive, send)
  File "C:\Users\tomer\AppData\Local\Programs\Python\Python310\lib\site-packages\starlette\middleware\errors.py", line 181, in __call__
    raise exc
  File "C:\Users\tomer\AppData\Local\Programs\Python\Python310\lib\site-packages\starlette\middleware\errors.py", line 159, in __call__
    await self.app(scope, receive, _send)
  File "C:\Users\tomer\AppData\Local\Programs\Python\Python310\lib\site-packages\starlette\middleware\cors.py", line 92, in __call__
    await self.simple_response(scope, receive, send, request_headers=headers)
  File "C:\Users\tomer\AppData\Local\Programs\Python\Python310\lib\site-packages\starlette\middleware\cors.py", line 147, in simple_response
    await self.app(scope, receive, send)
  File "C:\Users\tomer\AppData\Local\Programs\Python\Python310\lib\site-packages\starlette\exceptions.py", line 82, in __call__
    raise exc
  File "C:\Users\tomer\AppData\Local\Programs\Python\Python310\lib\site-packages\starlette\exceptions.py", line 71, in __call__
    await self.app(scope, receive, sender)
  File "C:\Users\tomer\AppData\Local\Programs\Python\Python310\lib\site-packages\fastapi\middleware\asyncexitstack.py", line 21, in __call__
    raise e
  File "C:\Users\tomer\AppData\Local\Programs\Python\Python310\lib\site-packages\fastapi\middleware\asyncexitstack.py", line 18, in __call__
    await self.app(scope, receive, send)
  File "C:\Users\tomer\AppData\Local\Programs\Python\Python310\lib\site-packages\starlette\routing.py", line 656, in __call__
    await route.handle(scope, receive, send)
  File "C:\Users\tomer\AppData\Local\Programs\Python\Python310\lib\site-packages\starlette\routing.py", line 259, in handle
    await self.app(scope, receive, send)
  File "C:\Users\tomer\AppData\Local\Programs\Python\Python310\lib\site-packages\starlette\routing.py", line 61, in app
    response = await func(request)
  File "C:\Users\tomer\AppData\Local\Programs\Python\Python310\lib\site-packages\fastapi\routing.py", line 227, in app
    raw_response = await run_endpoint_function(
  File "C:\Users\tomer\AppData\Local\Programs\Python\Python310\lib\site-packages\fastapi\routing.py", line 162, in run_endpoint_function
    return await run_in_threadpool(dependant.call, **values)
  File "C:\Users\tomer\AppData\Local\Programs\Python\Python310\lib\site-packages\starlette\concurrency.py", line 39, in run_in_threadpool
    return await anyio.to_thread.run_sync(func, *args)
  File "C:\Users\tomer\AppData\Local\Programs\Python\Python310\lib\site-packages\anyio\to_thread.py", line 28, in run_sync
    return await get_asynclib().run_sync_in_worker_thread(func, *args, cancellable=cancellable,
  File "C:\Users\tomer\AppData\Local\Programs\Python\Python310\lib\site-packages\anyio\_backends\_asyncio.py", line 818, in run_sync_in_worker_thread
    return await future
  File "C:\Users\tomer\AppData\Local\Programs\Python\Python310\lib\site-packages\anyio\_backends\_asyncio.py", line 754, in run
    result = context.run(func, *args)
  File "C:\Users\tomer\Desktop\sadna\Workshop\.\Code\Backend\Server-FastAPI\Server.py", line 153, in register
    res = service.register(user_info.id, user_info_dict)
  File "C:\Users\tomer\Desktop\sadna\Workshop\.\Code\Backend\Service\Service.py", line 137, in register
    response = Response(self.facade.register(guest_id, user_info))
  File "C:\Users\tomer\Desktop\sadna\Workshop\.\Code\Backend\Domain\Facade.py", line 103, in register
    return self.user_controller.register(guest_id, user_info)
  File "C:\Users\tomer\Desktop\sadna\Workshop\.\Code\Backend\Domain\Controllers\UserController.py", line 40, in register
    new_status = self.__users[user_id].register(member_info)
KeyError: ''
ERROR:uvicorn.error:Exception in ASGI application
Traceback (most recent call last):
  File "C:\Users\tomer\AppData\Local\Programs\Python\Python310\lib\site-packages\uvicorn\protocols\http\httptools_impl.py", line 372, in run_asgi
    result = await app(self.scope, self.receive, self.send)
  File "C:\Users\tomer\AppData\Local\Programs\Python\Python310\lib\site-packages\uvicorn\middleware\proxy_headers.py", line 75, in __call__
    return await self.app(scope, receive, send)
  File "C:\Users\tomer\AppData\Local\Programs\Python\Python310\lib\site-packages\fastapi\applications.py", line 261, in __call__
    await super().__call__(scope, receive, send)
  File "C:\Users\tomer\AppData\Local\Programs\Python\Python310\lib\site-packages\starlette\applications.py", line 112, in __call__
    await self.middleware_stack(scope, receive, send)
  File "C:\Users\tomer\AppData\Local\Programs\Python\Python310\lib\site-packages\starlette\middleware\errors.py", line 181, in __call__
    raise exc
  File "C:\Users\tomer\AppData\Local\Programs\Python\Python310\lib\site-packages\starlette\middleware\errors.py", line 159, in __call__
    await self.app(scope, receive, _send)
  File "C:\Users\tomer\AppData\Local\Programs\Python\Python310\lib\site-packages\starlette\middleware\cors.py", line 92, in __call__
    await self.simple_response(scope, receive, send, request_headers=headers)
  File "C:\Users\tomer\AppData\Local\Programs\Python\Python310\lib\site-packages\starlette\middleware\cors.py", line 147, in simple_response
    await self.app(scope, receive, send)
  File "C:\Users\tomer\AppData\Local\Programs\Python\Python310\lib\site-packages\starlette\exceptions.py", line 82, in __call__
    raise exc
  File "C:\Users\tomer\AppData\Local\Programs\Python\Python310\lib\site-packages\starlette\exceptions.py", line 71, in __call__
    await self.app(scope, receive, sender)
  File "C:\Users\tomer\AppData\Local\Programs\Python\Python310\lib\site-packages\fastapi\middleware\asyncexitstack.py", line 21, in __call__
    raise e
  File "C:\Users\tomer\AppData\Local\Programs\Python\Python310\lib\site-packages\fastapi\middleware\asyncexitstack.py", line 18, in __call__
    await self.app(scope, receive, send)
  File "C:\Users\tomer\AppData\Local\Programs\Python\Python310\lib\site-packages\starlette\routing.py", line 656, in __call__
    await route.handle(scope, receive, send)
  File "C:\Users\tomer\AppData\Local\Programs\Python\Python310\lib\site-packages\starlette\routing.py", line 259, in handle
    await self.app(scope, receive, send)
  File "C:\Users\tomer\AppData\Local\Programs\Python\Python310\lib\site-packages\starlette\routing.py", line 61, in app
    response = await func(request)
  File "C:\Users\tomer\AppData\Local\Programs\Python\Python310\lib\site-packages\fastapi\routing.py", line 227, in app
    raw_response = await run_endpoint_function(
  File "C:\Users\tomer\AppData\Local\Programs\Python\Python310\lib\site-packages\fastapi\routing.py", line 162, in run_endpoint_function
    return await run_in_threadpool(dependant.call, **values)
  File "C:\Users\tomer\AppData\Local\Programs\Python\Python310\lib\site-packages\starlette\concurrency.py", line 39, in run_in_threadpool
    return await anyio.to_thread.run_sync(func, *args)
  File "C:\Users\tomer\AppData\Local\Programs\Python\Python310\lib\site-packages\anyio\to_thread.py", line 28, in run_sync
    return await get_asynclib().run_sync_in_worker_thread(func, *args, cancellable=cancellable,
  File "C:\Users\tomer\AppData\Local\Programs\Python\Python310\lib\site-packages\anyio\_backends\_asyncio.py", line 818, in run_sync_in_worker_thread
    return await future
  File "C:\Users\tomer\AppData\Local\Programs\Python\Python310\lib\site-packages\anyio\_backends\_asyncio.py", line 754, in run
    result = context.run(func, *args)
  File "C:\Users\tomer\Desktop\sadna\Workshop\.\Code\Backend\Server-FastAPI\Server.py", line 153, in register
    res = service.register(user_info.id, user_info_dict)
  File "C:\Users\tomer\Desktop\sadna\Workshop\.\Code\Backend\Service\Service.py", line 137, in register
    response = Response(self.facade.register(guest_id, user_info))
  File "C:\Users\tomer\Desktop\sadna\Workshop\.\Code\Backend\Domain\Facade.py", line 103, in register
    return self.user_controller.register(guest_id, user_info)
  File "C:\Users\tomer\Desktop\sadna\Workshop\.\Code\Backend\Domain\Controllers\UserController.py", line 40, in register
    new_status = self.__users[user_id].register(member_info)
KeyError: ''
ERROR:uvicorn.error:Exception in ASGI application
Traceback (most recent call last):
  File "C:\Users\tomer\AppData\Local\Programs\Python\Python310\lib\site-packages\uvicorn\protocols\http\httptools_impl.py", line 372, in run_asgi
    result = await app(self.scope, self.receive, self.send)
  File "C:\Users\tomer\AppData\Local\Programs\Python\Python310\lib\site-packages\uvicorn\middleware\proxy_headers.py", line 75, in __call__
    return await self.app(scope, receive, send)
  File "C:\Users\tomer\AppData\Local\Programs\Python\Python310\lib\site-packages\fastapi\applications.py", line 261, in __call__
    await super().__call__(scope, receive, send)
  File "C:\Users\tomer\AppData\Local\Programs\Python\Python310\lib\site-packages\starlette\applications.py", line 112, in __call__
    await self.middleware_stack(scope, receive, send)
  File "C:\Users\tomer\AppData\Local\Programs\Python\Python310\lib\site-packages\starlette\middleware\errors.py", line 181, in __call__
    raise exc
  File "C:\Users\tomer\AppData\Local\Programs\Python\Python310\lib\site-packages\starlette\middleware\errors.py", line 159, in __call__
    await self.app(scope, receive, _send)
  File "C:\Users\tomer\AppData\Local\Programs\Python\Python310\lib\site-packages\starlette\middleware\cors.py", line 92, in __call__
    await self.simple_response(scope, receive, send, request_headers=headers)
  File "C:\Users\tomer\AppData\Local\Programs\Python\Python310\lib\site-packages\starlette\middleware\cors.py", line 147, in simple_response
    await self.app(scope, receive, send)
  File "C:\Users\tomer\AppData\Local\Programs\Python\Python310\lib\site-packages\starlette\exceptions.py", line 82, in __call__
    raise exc
  File "C:\Users\tomer\AppData\Local\Programs\Python\Python310\lib\site-packages\starlette\exceptions.py", line 71, in __call__
    await self.app(scope, receive, sender)
  File "C:\Users\tomer\AppData\Local\Programs\Python\Python310\lib\site-packages\fastapi\middleware\asyncexitstack.py", line 21, in __call__
    raise e
  File "C:\Users\tomer\AppData\Local\Programs\Python\Python310\lib\site-packages\fastapi\middleware\asyncexitstack.py", line 18, in __call__
    await self.app(scope, receive, send)
  File "C:\Users\tomer\AppData\Local\Programs\Python\Python310\lib\site-packages\starlette\routing.py", line 656, in __call__
    await route.handle(scope, receive, send)
  File "C:\Users\tomer\AppData\Local\Programs\Python\Python310\lib\site-packages\starlette\routing.py", line 259, in handle
    await self.app(scope, receive, send)
  File "C:\Users\tomer\AppData\Local\Programs\Python\Python310\lib\site-packages\starlette\routing.py", line 61, in app
    response = await func(request)
  File "C:\Users\tomer\AppData\Local\Programs\Python\Python310\lib\site-packages\fastapi\routing.py", line 227, in app
    raw_response = await run_endpoint_function(
  File "C:\Users\tomer\AppData\Local\Programs\Python\Python310\lib\site-packages\fastapi\routing.py", line 162, in run_endpoint_function
    return await run_in_threadpool(dependant.call, **values)
  File "C:\Users\tomer\AppData\Local\Programs\Python\Python310\lib\site-packages\starlette\concurrency.py", line 39, in run_in_threadpool
    return await anyio.to_thread.run_sync(func, *args)
  File "C:\Users\tomer\AppData\Local\Programs\Python\Python310\lib\site-packages\anyio\to_thread.py", line 28, in run_sync
    return await get_asynclib().run_sync_in_worker_thread(func, *args, cancellable=cancellable,
  File "C:\Users\tomer\AppData\Local\Programs\Python\Python310\lib\site-packages\anyio\_backends\_asyncio.py", line 818, in run_sync_in_worker_thread
    return await future
  File "C:\Users\tomer\AppData\Local\Programs\Python\Python310\lib\site-packages\anyio\_backends\_asyncio.py", line 754, in run
    result = context.run(func, *args)
  File "C:\Users\tomer\Desktop\sadna\Workshop\.\Code\Backend\Server-FastAPI\Server.py", line 153, in register
    res = service.register(user_info.id, user_info_dict)
  File "C:\Users\tomer\Desktop\sadna\Workshop\.\Code\Backend\Service\Service.py", line 137, in register
    response = Response(self.facade.register(guest_id, user_info))
  File "C:\Users\tomer\Desktop\sadna\Workshop\.\Code\Backend\Domain\Facade.py", line 103, in register
    return self.user_controller.register(guest_id, user_info)
  File "C:\Users\tomer\Desktop\sadna\Workshop\.\Code\Backend\Domain\Controllers\UserController.py", line 40, in register
    new_status = self.__users[user_id].register(member_info)
KeyError: ''
ERROR:uvicorn.error:Exception in ASGI application
Traceback (most recent call last):
  File "C:\Users\tomer\AppData\Local\Programs\Python\Python310\lib\site-packages\uvicorn\protocols\http\httptools_impl.py", line 372, in run_asgi
    result = await app(self.scope, self.receive, self.send)
  File "C:\Users\tomer\AppData\Local\Programs\Python\Python310\lib\site-packages\uvicorn\middleware\proxy_headers.py", line 75, in __call__
    return await self.app(scope, receive, send)
  File "C:\Users\tomer\AppData\Local\Programs\Python\Python310\lib\site-packages\fastapi\applications.py", line 261, in __call__
    await super().__call__(scope, receive, send)
  File "C:\Users\tomer\AppData\Local\Programs\Python\Python310\lib\site-packages\starlette\applications.py", line 112, in __call__
    await self.middleware_stack(scope, receive, send)
  File "C:\Users\tomer\AppData\Local\Programs\Python\Python310\lib\site-packages\starlette\middleware\errors.py", line 181, in __call__
    raise exc
  File "C:\Users\tomer\AppData\Local\Programs\Python\Python310\lib\site-packages\starlette\middleware\errors.py", line 159, in __call__
    await self.app(scope, receive, _send)
  File "C:\Users\tomer\AppData\Local\Programs\Python\Python310\lib\site-packages\starlette\middleware\cors.py", line 92, in __call__
    await self.simple_response(scope, receive, send, request_headers=headers)
  File "C:\Users\tomer\AppData\Local\Programs\Python\Python310\lib\site-packages\starlette\middleware\cors.py", line 147, in simple_response
    await self.app(scope, receive, send)
  File "C:\Users\tomer\AppData\Local\Programs\Python\Python310\lib\site-packages\starlette\exceptions.py", line 82, in __call__
    raise exc
  File "C:\Users\tomer\AppData\Local\Programs\Python\Python310\lib\site-packages\starlette\exceptions.py", line 71, in __call__
    await self.app(scope, receive, sender)
  File "C:\Users\tomer\AppData\Local\Programs\Python\Python310\lib\site-packages\fastapi\middleware\asyncexitstack.py", line 21, in __call__
    raise e
  File "C:\Users\tomer\AppData\Local\Programs\Python\Python310\lib\site-packages\fastapi\middleware\asyncexitstack.py", line 18, in __call__
    await self.app(scope, receive, send)
  File "C:\Users\tomer\AppData\Local\Programs\Python\Python310\lib\site-packages\starlette\routing.py", line 656, in __call__
    await route.handle(scope, receive, send)
  File "C:\Users\tomer\AppData\Local\Programs\Python\Python310\lib\site-packages\starlette\routing.py", line 259, in handle
    await self.app(scope, receive, send)
  File "C:\Users\tomer\AppData\Local\Programs\Python\Python310\lib\site-packages\starlette\routing.py", line 61, in app
    response = await func(request)
  File "C:\Users\tomer\AppData\Local\Programs\Python\Python310\lib\site-packages\fastapi\routing.py", line 227, in app
    raw_response = await run_endpoint_function(
  File "C:\Users\tomer\AppData\Local\Programs\Python\Python310\lib\site-packages\fastapi\routing.py", line 162, in run_endpoint_function
    return await run_in_threadpool(dependant.call, **values)
  File "C:\Users\tomer\AppData\Local\Programs\Python\Python310\lib\site-packages\starlette\concurrency.py", line 39, in run_in_threadpool
    return await anyio.to_thread.run_sync(func, *args)
  File "C:\Users\tomer\AppData\Local\Programs\Python\Python310\lib\site-packages\anyio\to_thread.py", line 28, in run_sync
    return await get_asynclib().run_sync_in_worker_thread(func, *args, cancellable=cancellable,
  File "C:\Users\tomer\AppData\Local\Programs\Python\Python310\lib\site-packages\anyio\_backends\_asyncio.py", line 818, in run_sync_in_worker_thread
    return await future
  File "C:\Users\tomer\AppData\Local\Programs\Python\Python310\lib\site-packages\anyio\_backends\_asyncio.py", line 754, in run
    result = context.run(func, *args)
  File "C:\Users\tomer\Desktop\sadna\Workshop\.\Code\Backend\Server-FastAPI\Server.py", line 153, in register
    res = service.register(user_info.id, user_info_dict)
  File "C:\Users\tomer\Desktop\sadna\Workshop\.\Code\Backend\Service\Service.py", line 137, in register
    response = Response(self.facade.register(guest_id, user_info))
  File "C:\Users\tomer\Desktop\sadna\Workshop\.\Code\Backend\Domain\Facade.py", line 103, in register
    return self.user_controller.register(guest_id, user_info)
  File "C:\Users\tomer\Desktop\sadna\Workshop\.\Code\Backend\Domain\Controllers\UserController.py", line 40, in register
    new_status = self.__users[user_id].register(member_info)
KeyError: ''
ERROR:uvicorn.error:Exception in ASGI application
Traceback (most recent call last):
  File "C:\Users\tomer\AppData\Local\Programs\Python\Python310\lib\site-packages\uvicorn\protocols\http\httptools_impl.py", line 372, in run_asgi
    result = await app(self.scope, self.receive, self.send)
  File "C:\Users\tomer\AppData\Local\Programs\Python\Python310\lib\site-packages\uvicorn\middleware\proxy_headers.py", line 75, in __call__
    return await self.app(scope, receive, send)
  File "C:\Users\tomer\AppData\Local\Programs\Python\Python310\lib\site-packages\fastapi\applications.py", line 261, in __call__
    await super().__call__(scope, receive, send)
  File "C:\Users\tomer\AppData\Local\Programs\Python\Python310\lib\site-packages\starlette\applications.py", line 112, in __call__
    await self.middleware_stack(scope, receive, send)
  File "C:\Users\tomer\AppData\Local\Programs\Python\Python310\lib\site-packages\starlette\middleware\errors.py", line 181, in __call__
    raise exc
  File "C:\Users\tomer\AppData\Local\Programs\Python\Python310\lib\site-packages\starlette\middleware\errors.py", line 159, in __call__
    await self.app(scope, receive, _send)
  File "C:\Users\tomer\AppData\Local\Programs\Python\Python310\lib\site-packages\starlette\middleware\cors.py", line 92, in __call__
    await self.simple_response(scope, receive, send, request_headers=headers)
  File "C:\Users\tomer\AppData\Local\Programs\Python\Python310\lib\site-packages\starlette\middleware\cors.py", line 147, in simple_response
    await self.app(scope, receive, send)
  File "C:\Users\tomer\AppData\Local\Programs\Python\Python310\lib\site-packages\starlette\exceptions.py", line 82, in __call__
    raise exc
  File "C:\Users\tomer\AppData\Local\Programs\Python\Python310\lib\site-packages\starlette\exceptions.py", line 71, in __call__
    await self.app(scope, receive, sender)
  File "C:\Users\tomer\AppData\Local\Programs\Python\Python310\lib\site-packages\fastapi\middleware\asyncexitstack.py", line 21, in __call__
    raise e
  File "C:\Users\tomer\AppData\Local\Programs\Python\Python310\lib\site-packages\fastapi\middleware\asyncexitstack.py", line 18, in __call__
    await self.app(scope, receive, send)
  File "C:\Users\tomer\AppData\Local\Programs\Python\Python310\lib\site-packages\starlette\routing.py", line 656, in __call__
    await route.handle(scope, receive, send)
  File "C:\Users\tomer\AppData\Local\Programs\Python\Python310\lib\site-packages\starlette\routing.py", line 259, in handle
    await self.app(scope, receive, send)
  File "C:\Users\tomer\AppData\Local\Programs\Python\Python310\lib\site-packages\starlette\routing.py", line 61, in app
    response = await func(request)
  File "C:\Users\tomer\AppData\Local\Programs\Python\Python310\lib\site-packages\fastapi\routing.py", line 227, in app
    raw_response = await run_endpoint_function(
  File "C:\Users\tomer\AppData\Local\Programs\Python\Python310\lib\site-packages\fastapi\routing.py", line 162, in run_endpoint_function
    return await run_in_threadpool(dependant.call, **values)
  File "C:\Users\tomer\AppData\Local\Programs\Python\Python310\lib\site-packages\starlette\concurrency.py", line 39, in run_in_threadpool
    return await anyio.to_thread.run_sync(func, *args)
  File "C:\Users\tomer\AppData\Local\Programs\Python\Python310\lib\site-packages\anyio\to_thread.py", line 28, in run_sync
    return await get_asynclib().run_sync_in_worker_thread(func, *args, cancellable=cancellable,
  File "C:\Users\tomer\AppData\Local\Programs\Python\Python310\lib\site-packages\anyio\_backends\_asyncio.py", line 818, in run_sync_in_worker_thread
    return await future
  File "C:\Users\tomer\AppData\Local\Programs\Python\Python310\lib\site-packages\anyio\_backends\_asyncio.py", line 754, in run
    result = context.run(func, *args)
  File "C:\Users\tomer\Desktop\sadna\Workshop\.\Code\Backend\Server-FastAPI\Server.py", line 153, in register
    res = service.register(user_info.id, user_info_dict)
  File "C:\Users\tomer\Desktop\sadna\Workshop\.\Code\Backend\Service\Service.py", line 137, in register
    response = Response(self.facade.register(guest_id, user_info))
  File "C:\Users\tomer\Desktop\sadna\Workshop\.\Code\Backend\Domain\Facade.py", line 103, in register
    return self.user_controller.register(guest_id, user_info)
  File "C:\Users\tomer\Desktop\sadna\Workshop\.\Code\Backend\Domain\Controllers\UserController.py", line 40, in register
    new_status = self.__users[user_id].register(member_info)
KeyError: ''
CRITICAL:root:User is already an Owner of this store
INFO:uvicorn.error:Shutting down
INFO:uvicorn.error:Waiting for application shutdown.
INFO:uvicorn.error:Application shutdown complete.
INFO:uvicorn.error:Finished server process [12584]
INFO:uvicorn.error:Started server process [20420]
INFO:uvicorn.error:Waiting for application startup.
INFO:uvicorn.error:Application startup complete.
ERROR:uvicorn.error:Exception in ASGI application
Traceback (most recent call last):
  File "C:\Users\tomer\AppData\Local\Programs\Python\Python310\lib\site-packages\uvicorn\protocols\http\httptools_impl.py", line 372, in run_asgi
    result = await app(self.scope, self.receive, self.send)
  File "C:\Users\tomer\AppData\Local\Programs\Python\Python310\lib\site-packages\uvicorn\middleware\proxy_headers.py", line 75, in __call__
    return await self.app(scope, receive, send)
  File "C:\Users\tomer\AppData\Local\Programs\Python\Python310\lib\site-packages\fastapi\applications.py", line 261, in __call__
    await super().__call__(scope, receive, send)
  File "C:\Users\tomer\AppData\Local\Programs\Python\Python310\lib\site-packages\starlette\applications.py", line 112, in __call__
    await self.middleware_stack(scope, receive, send)
  File "C:\Users\tomer\AppData\Local\Programs\Python\Python310\lib\site-packages\starlette\middleware\errors.py", line 181, in __call__
    raise exc
  File "C:\Users\tomer\AppData\Local\Programs\Python\Python310\lib\site-packages\starlette\middleware\errors.py", line 159, in __call__
    await self.app(scope, receive, _send)
  File "C:\Users\tomer\AppData\Local\Programs\Python\Python310\lib\site-packages\starlette\middleware\cors.py", line 92, in __call__
    await self.simple_response(scope, receive, send, request_headers=headers)
  File "C:\Users\tomer\AppData\Local\Programs\Python\Python310\lib\site-packages\starlette\middleware\cors.py", line 147, in simple_response
    await self.app(scope, receive, send)
  File "C:\Users\tomer\AppData\Local\Programs\Python\Python310\lib\site-packages\starlette\exceptions.py", line 82, in __call__
    raise exc
  File "C:\Users\tomer\AppData\Local\Programs\Python\Python310\lib\site-packages\starlette\exceptions.py", line 71, in __call__
    await self.app(scope, receive, sender)
  File "C:\Users\tomer\AppData\Local\Programs\Python\Python310\lib\site-packages\fastapi\middleware\asyncexitstack.py", line 21, in __call__
    raise e
  File "C:\Users\tomer\AppData\Local\Programs\Python\Python310\lib\site-packages\fastapi\middleware\asyncexitstack.py", line 18, in __call__
    await self.app(scope, receive, send)
  File "C:\Users\tomer\AppData\Local\Programs\Python\Python310\lib\site-packages\starlette\routing.py", line 656, in __call__
    await route.handle(scope, receive, send)
  File "C:\Users\tomer\AppData\Local\Programs\Python\Python310\lib\site-packages\starlette\routing.py", line 259, in handle
    await self.app(scope, receive, send)
  File "C:\Users\tomer\AppData\Local\Programs\Python\Python310\lib\site-packages\starlette\routing.py", line 61, in app
    response = await func(request)
  File "C:\Users\tomer\AppData\Local\Programs\Python\Python310\lib\site-packages\fastapi\routing.py", line 227, in app
    raw_response = await run_endpoint_function(
  File "C:\Users\tomer\AppData\Local\Programs\Python\Python310\lib\site-packages\fastapi\routing.py", line 162, in run_endpoint_function
    return await run_in_threadpool(dependant.call, **values)
  File "C:\Users\tomer\AppData\Local\Programs\Python\Python310\lib\site-packages\starlette\concurrency.py", line 39, in run_in_threadpool
    return await anyio.to_thread.run_sync(func, *args)
  File "C:\Users\tomer\AppData\Local\Programs\Python\Python310\lib\site-packages\anyio\to_thread.py", line 28, in run_sync
    return await get_asynclib().run_sync_in_worker_thread(func, *args, cancellable=cancellable,
  File "C:\Users\tomer\AppData\Local\Programs\Python\Python310\lib\site-packages\anyio\_backends\_asyncio.py", line 818, in run_sync_in_worker_thread
    return await future
  File "C:\Users\tomer\AppData\Local\Programs\Python\Python310\lib\site-packages\anyio\_backends\_asyncio.py", line 754, in run
    result = context.run(func, *args)
  File "C:\Users\tomer\Desktop\sadna\Workshop\.\Code\Backend\Server-FastAPI\Server.py", line 211, in get_users_stores
    res = service.get_users_stores(user_id)
  File "C:\Users\tomer\Desktop\sadna\Workshop\.\Code\Backend\Service\Service.py", line 661, in get_users_stores
    response = Response(self.facade.get_users_stores(user_id))
  File "C:\Users\tomer\Desktop\sadna\Workshop\.\Code\Backend\Domain\Facade.py", line 718, in get_users_stores
    member_id = self.user_controller.get_users_username(user_id)
  File "C:\Users\tomer\Desktop\sadna\Workshop\.\Code\Backend\Domain\Controllers\UserController.py", line 71, in get_users_username
    return Response(self.__users[user_id].get_username())
  File "C:\Users\tomer\Desktop\sadna\Workshop\.\Code\Backend\Domain\Visitor.py", line 55, in get_username
    return self.__status.get_username()
  File "C:\Users\tomer\Desktop\sadna\Workshop\.\Code\Backend\Domain\VisitorStates\GuestState.py", line 19, in get_username
    raise Exception("guest doesnt have username")
Exception: guest doesnt have username
ERROR:uvicorn.error:Exception in ASGI application
Traceback (most recent call last):
  File "C:\Users\tomer\AppData\Local\Programs\Python\Python310\lib\site-packages\uvicorn\protocols\http\httptools_impl.py", line 372, in run_asgi
    result = await app(self.scope, self.receive, self.send)
  File "C:\Users\tomer\AppData\Local\Programs\Python\Python310\lib\site-packages\uvicorn\middleware\proxy_headers.py", line 75, in __call__
    return await self.app(scope, receive, send)
  File "C:\Users\tomer\AppData\Local\Programs\Python\Python310\lib\site-packages\fastapi\applications.py", line 261, in __call__
    await super().__call__(scope, receive, send)
  File "C:\Users\tomer\AppData\Local\Programs\Python\Python310\lib\site-packages\starlette\applications.py", line 112, in __call__
    await self.middleware_stack(scope, receive, send)
  File "C:\Users\tomer\AppData\Local\Programs\Python\Python310\lib\site-packages\starlette\middleware\errors.py", line 181, in __call__
    raise exc
  File "C:\Users\tomer\AppData\Local\Programs\Python\Python310\lib\site-packages\starlette\middleware\errors.py", line 159, in __call__
    await self.app(scope, receive, _send)
  File "C:\Users\tomer\AppData\Local\Programs\Python\Python310\lib\site-packages\starlette\middleware\cors.py", line 92, in __call__
    await self.simple_response(scope, receive, send, request_headers=headers)
  File "C:\Users\tomer\AppData\Local\Programs\Python\Python310\lib\site-packages\starlette\middleware\cors.py", line 147, in simple_response
    await self.app(scope, receive, send)
  File "C:\Users\tomer\AppData\Local\Programs\Python\Python310\lib\site-packages\starlette\exceptions.py", line 82, in __call__
    raise exc
  File "C:\Users\tomer\AppData\Local\Programs\Python\Python310\lib\site-packages\starlette\exceptions.py", line 71, in __call__
    await self.app(scope, receive, sender)
  File "C:\Users\tomer\AppData\Local\Programs\Python\Python310\lib\site-packages\fastapi\middleware\asyncexitstack.py", line 21, in __call__
    raise e
  File "C:\Users\tomer\AppData\Local\Programs\Python\Python310\lib\site-packages\fastapi\middleware\asyncexitstack.py", line 18, in __call__
    await self.app(scope, receive, send)
  File "C:\Users\tomer\AppData\Local\Programs\Python\Python310\lib\site-packages\starlette\routing.py", line 656, in __call__
    await route.handle(scope, receive, send)
  File "C:\Users\tomer\AppData\Local\Programs\Python\Python310\lib\site-packages\starlette\routing.py", line 259, in handle
    await self.app(scope, receive, send)
  File "C:\Users\tomer\AppData\Local\Programs\Python\Python310\lib\site-packages\starlette\routing.py", line 61, in app
    response = await func(request)
  File "C:\Users\tomer\AppData\Local\Programs\Python\Python310\lib\site-packages\fastapi\routing.py", line 227, in app
    raw_response = await run_endpoint_function(
  File "C:\Users\tomer\AppData\Local\Programs\Python\Python310\lib\site-packages\fastapi\routing.py", line 162, in run_endpoint_function
    return await run_in_threadpool(dependant.call, **values)
  File "C:\Users\tomer\AppData\Local\Programs\Python\Python310\lib\site-packages\starlette\concurrency.py", line 39, in run_in_threadpool
    return await anyio.to_thread.run_sync(func, *args)
  File "C:\Users\tomer\AppData\Local\Programs\Python\Python310\lib\site-packages\anyio\to_thread.py", line 28, in run_sync
    return await get_asynclib().run_sync_in_worker_thread(func, *args, cancellable=cancellable,
  File "C:\Users\tomer\AppData\Local\Programs\Python\Python310\lib\site-packages\anyio\_backends\_asyncio.py", line 818, in run_sync_in_worker_thread
    return await future
  File "C:\Users\tomer\AppData\Local\Programs\Python\Python310\lib\site-packages\anyio\_backends\_asyncio.py", line 754, in run
    result = context.run(func, *args)
  File "C:\Users\tomer\Desktop\sadna\Workshop\.\Code\Backend\Server-FastAPI\Server.py", line 259, in open_store
    res = service.open_store(store_name.id, store_name.store_name)
  File "C:\Users\tomer\Desktop\sadna\Workshop\.\Code\Backend\Service\Service.py", line 274, in open_store
    response = Response(self.facade.open_store(user_id, store_name))
  File "C:\Users\tomer\Desktop\sadna\Workshop\.\Code\Backend\Domain\Facade.py", line 290, in open_store
    response_member_id = self.user_controller.get_users_username(user_id)
  File "C:\Users\tomer\Desktop\sadna\Workshop\.\Code\Backend\Domain\Controllers\UserController.py", line 71, in get_users_username
    return Response(self.__users[user_id].get_username())
  File "C:\Users\tomer\Desktop\sadna\Workshop\.\Code\Backend\Domain\Visitor.py", line 55, in get_username
    return self.__status.get_username()
  File "C:\Users\tomer\Desktop\sadna\Workshop\.\Code\Backend\Domain\VisitorStates\GuestState.py", line 19, in get_username
    raise Exception("guest doesnt have username")
Exception: guest doesnt have username
CRITICAL:root:member is not logged in
INFO:uvicorn.error:Shutting down
INFO:uvicorn.error:Waiting for application shutdown.
INFO:uvicorn.error:Application shutdown complete.
INFO:uvicorn.error:Finished server process [20420]
INFO:uvicorn.error:Started server process [11244]
INFO:uvicorn.error:Waiting for application startup.
INFO:uvicorn.error:Application startup complete.
ERROR:uvicorn.error:Exception in ASGI application
Traceback (most recent call last):
  File "C:\Users\tomer\AppData\Local\Programs\Python\Python310\lib\site-packages\uvicorn\protocols\http\httptools_impl.py", line 372, in run_asgi
    result = await app(self.scope, self.receive, self.send)
  File "C:\Users\tomer\AppData\Local\Programs\Python\Python310\lib\site-packages\uvicorn\middleware\proxy_headers.py", line 75, in __call__
    return await self.app(scope, receive, send)
  File "C:\Users\tomer\AppData\Local\Programs\Python\Python310\lib\site-packages\fastapi\applications.py", line 261, in __call__
    await super().__call__(scope, receive, send)
  File "C:\Users\tomer\AppData\Local\Programs\Python\Python310\lib\site-packages\starlette\applications.py", line 112, in __call__
    await self.middleware_stack(scope, receive, send)
  File "C:\Users\tomer\AppData\Local\Programs\Python\Python310\lib\site-packages\starlette\middleware\errors.py", line 181, in __call__
    raise exc
  File "C:\Users\tomer\AppData\Local\Programs\Python\Python310\lib\site-packages\starlette\middleware\errors.py", line 159, in __call__
    await self.app(scope, receive, _send)
  File "C:\Users\tomer\AppData\Local\Programs\Python\Python310\lib\site-packages\starlette\middleware\cors.py", line 92, in __call__
    await self.simple_response(scope, receive, send, request_headers=headers)
  File "C:\Users\tomer\AppData\Local\Programs\Python\Python310\lib\site-packages\starlette\middleware\cors.py", line 147, in simple_response
    await self.app(scope, receive, send)
  File "C:\Users\tomer\AppData\Local\Programs\Python\Python310\lib\site-packages\starlette\exceptions.py", line 82, in __call__
    raise exc
  File "C:\Users\tomer\AppData\Local\Programs\Python\Python310\lib\site-packages\starlette\exceptions.py", line 71, in __call__
    await self.app(scope, receive, sender)
  File "C:\Users\tomer\AppData\Local\Programs\Python\Python310\lib\site-packages\fastapi\middleware\asyncexitstack.py", line 21, in __call__
    raise e
  File "C:\Users\tomer\AppData\Local\Programs\Python\Python310\lib\site-packages\fastapi\middleware\asyncexitstack.py", line 18, in __call__
    await self.app(scope, receive, send)
  File "C:\Users\tomer\AppData\Local\Programs\Python\Python310\lib\site-packages\starlette\routing.py", line 656, in __call__
    await route.handle(scope, receive, send)
  File "C:\Users\tomer\AppData\Local\Programs\Python\Python310\lib\site-packages\starlette\routing.py", line 259, in handle
    await self.app(scope, receive, send)
  File "C:\Users\tomer\AppData\Local\Programs\Python\Python310\lib\site-packages\starlette\routing.py", line 61, in app
    response = await func(request)
  File "C:\Users\tomer\AppData\Local\Programs\Python\Python310\lib\site-packages\fastapi\routing.py", line 227, in app
    raw_response = await run_endpoint_function(
  File "C:\Users\tomer\AppData\Local\Programs\Python\Python310\lib\site-packages\fastapi\routing.py", line 162, in run_endpoint_function
    return await run_in_threadpool(dependant.call, **values)
  File "C:\Users\tomer\AppData\Local\Programs\Python\Python310\lib\site-packages\starlette\concurrency.py", line 39, in run_in_threadpool
    return await anyio.to_thread.run_sync(func, *args)
  File "C:\Users\tomer\AppData\Local\Programs\Python\Python310\lib\site-packages\anyio\to_thread.py", line 28, in run_sync
    return await get_asynclib().run_sync_in_worker_thread(func, *args, cancellable=cancellable,
  File "C:\Users\tomer\AppData\Local\Programs\Python\Python310\lib\site-packages\anyio\_backends\_asyncio.py", line 818, in run_sync_in_worker_thread
    return await future
  File "C:\Users\tomer\AppData\Local\Programs\Python\Python310\lib\site-packages\anyio\_backends\_asyncio.py", line 754, in run
    result = context.run(func, *args)
  File "C:\Users\tomer\Desktop\sadna\Workshop\.\Code\Backend\Server-FastAPI\Server.py", line 153, in register
    res = service.register(user_info.id, user_info_dict)
  File "C:\Users\tomer\Desktop\sadna\Workshop\.\Code\Backend\Service\Service.py", line 137, in register
    response = Response(self.facade.register(guest_id, user_info))
  File "C:\Users\tomer\Desktop\sadna\Workshop\.\Code\Backend\Domain\Facade.py", line 103, in register
    return self.user_controller.register(guest_id, user_info)
  File "C:\Users\tomer\Desktop\sadna\Workshop\.\Code\Backend\Domain\Controllers\UserController.py", line 42, in register
    new_member = self.__users[user_id].register(member_info)
KeyError: '2'
ERROR:uvicorn.error:Exception in ASGI application
Traceback (most recent call last):
  File "C:\Users\tomer\AppData\Local\Programs\Python\Python310\lib\site-packages\uvicorn\protocols\http\httptools_impl.py", line 372, in run_asgi
    result = await app(self.scope, self.receive, self.send)
  File "C:\Users\tomer\AppData\Local\Programs\Python\Python310\lib\site-packages\uvicorn\middleware\proxy_headers.py", line 75, in __call__
    return await self.app(scope, receive, send)
  File "C:\Users\tomer\AppData\Local\Programs\Python\Python310\lib\site-packages\fastapi\applications.py", line 261, in __call__
    await super().__call__(scope, receive, send)
  File "C:\Users\tomer\AppData\Local\Programs\Python\Python310\lib\site-packages\starlette\applications.py", line 112, in __call__
    await self.middleware_stack(scope, receive, send)
  File "C:\Users\tomer\AppData\Local\Programs\Python\Python310\lib\site-packages\starlette\middleware\errors.py", line 181, in __call__
    raise exc
  File "C:\Users\tomer\AppData\Local\Programs\Python\Python310\lib\site-packages\starlette\middleware\errors.py", line 159, in __call__
    await self.app(scope, receive, _send)
  File "C:\Users\tomer\AppData\Local\Programs\Python\Python310\lib\site-packages\starlette\middleware\cors.py", line 92, in __call__
    await self.simple_response(scope, receive, send, request_headers=headers)
  File "C:\Users\tomer\AppData\Local\Programs\Python\Python310\lib\site-packages\starlette\middleware\cors.py", line 147, in simple_response
    await self.app(scope, receive, send)
  File "C:\Users\tomer\AppData\Local\Programs\Python\Python310\lib\site-packages\starlette\exceptions.py", line 82, in __call__
    raise exc
  File "C:\Users\tomer\AppData\Local\Programs\Python\Python310\lib\site-packages\starlette\exceptions.py", line 71, in __call__
    await self.app(scope, receive, sender)
  File "C:\Users\tomer\AppData\Local\Programs\Python\Python310\lib\site-packages\fastapi\middleware\asyncexitstack.py", line 21, in __call__
    raise e
  File "C:\Users\tomer\AppData\Local\Programs\Python\Python310\lib\site-packages\fastapi\middleware\asyncexitstack.py", line 18, in __call__
    await self.app(scope, receive, send)
  File "C:\Users\tomer\AppData\Local\Programs\Python\Python310\lib\site-packages\starlette\routing.py", line 656, in __call__
    await route.handle(scope, receive, send)
  File "C:\Users\tomer\AppData\Local\Programs\Python\Python310\lib\site-packages\starlette\routing.py", line 259, in handle
    await self.app(scope, receive, send)
  File "C:\Users\tomer\AppData\Local\Programs\Python\Python310\lib\site-packages\starlette\routing.py", line 61, in app
    response = await func(request)
  File "C:\Users\tomer\AppData\Local\Programs\Python\Python310\lib\site-packages\fastapi\routing.py", line 227, in app
    raw_response = await run_endpoint_function(
  File "C:\Users\tomer\AppData\Local\Programs\Python\Python310\lib\site-packages\fastapi\routing.py", line 162, in run_endpoint_function
    return await run_in_threadpool(dependant.call, **values)
  File "C:\Users\tomer\AppData\Local\Programs\Python\Python310\lib\site-packages\starlette\concurrency.py", line 39, in run_in_threadpool
    return await anyio.to_thread.run_sync(func, *args)
  File "C:\Users\tomer\AppData\Local\Programs\Python\Python310\lib\site-packages\anyio\to_thread.py", line 28, in run_sync
    return await get_asynclib().run_sync_in_worker_thread(func, *args, cancellable=cancellable,
  File "C:\Users\tomer\AppData\Local\Programs\Python\Python310\lib\site-packages\anyio\_backends\_asyncio.py", line 818, in run_sync_in_worker_thread
    return await future
  File "C:\Users\tomer\AppData\Local\Programs\Python\Python310\lib\site-packages\anyio\_backends\_asyncio.py", line 754, in run
    result = context.run(func, *args)
  File "C:\Users\tomer\Desktop\sadna\Workshop\.\Code\Backend\Server-FastAPI\Server.py", line 153, in register
    res = service.register(user_info.id, user_info_dict)
  File "C:\Users\tomer\Desktop\sadna\Workshop\.\Code\Backend\Service\Service.py", line 137, in register
    response = Response(self.facade.register(guest_id, user_info))
  File "C:\Users\tomer\Desktop\sadna\Workshop\.\Code\Backend\Domain\Facade.py", line 103, in register
    return self.user_controller.register(guest_id, user_info)
  File "C:\Users\tomer\Desktop\sadna\Workshop\.\Code\Backend\Domain\Controllers\UserController.py", line 42, in register
    new_member = self.__users[user_id].register(member_info)
KeyError: '2'
ERROR:uvicorn.error:Exception in ASGI application
Traceback (most recent call last):
  File "C:\Users\tomer\AppData\Local\Programs\Python\Python310\lib\site-packages\uvicorn\protocols\http\httptools_impl.py", line 372, in run_asgi
    result = await app(self.scope, self.receive, self.send)
  File "C:\Users\tomer\AppData\Local\Programs\Python\Python310\lib\site-packages\uvicorn\middleware\proxy_headers.py", line 75, in __call__
    return await self.app(scope, receive, send)
  File "C:\Users\tomer\AppData\Local\Programs\Python\Python310\lib\site-packages\fastapi\applications.py", line 261, in __call__
    await super().__call__(scope, receive, send)
  File "C:\Users\tomer\AppData\Local\Programs\Python\Python310\lib\site-packages\starlette\applications.py", line 112, in __call__
    await self.middleware_stack(scope, receive, send)
  File "C:\Users\tomer\AppData\Local\Programs\Python\Python310\lib\site-packages\starlette\middleware\errors.py", line 181, in __call__
    raise exc
  File "C:\Users\tomer\AppData\Local\Programs\Python\Python310\lib\site-packages\starlette\middleware\errors.py", line 159, in __call__
    await self.app(scope, receive, _send)
  File "C:\Users\tomer\AppData\Local\Programs\Python\Python310\lib\site-packages\starlette\middleware\cors.py", line 92, in __call__
    await self.simple_response(scope, receive, send, request_headers=headers)
  File "C:\Users\tomer\AppData\Local\Programs\Python\Python310\lib\site-packages\starlette\middleware\cors.py", line 147, in simple_response
    await self.app(scope, receive, send)
  File "C:\Users\tomer\AppData\Local\Programs\Python\Python310\lib\site-packages\starlette\exceptions.py", line 82, in __call__
    raise exc
  File "C:\Users\tomer\AppData\Local\Programs\Python\Python310\lib\site-packages\starlette\exceptions.py", line 71, in __call__
    await self.app(scope, receive, sender)
  File "C:\Users\tomer\AppData\Local\Programs\Python\Python310\lib\site-packages\fastapi\middleware\asyncexitstack.py", line 21, in __call__
    raise e
  File "C:\Users\tomer\AppData\Local\Programs\Python\Python310\lib\site-packages\fastapi\middleware\asyncexitstack.py", line 18, in __call__
    await self.app(scope, receive, send)
  File "C:\Users\tomer\AppData\Local\Programs\Python\Python310\lib\site-packages\starlette\routing.py", line 656, in __call__
    await route.handle(scope, receive, send)
  File "C:\Users\tomer\AppData\Local\Programs\Python\Python310\lib\site-packages\starlette\routing.py", line 259, in handle
    await self.app(scope, receive, send)
  File "C:\Users\tomer\AppData\Local\Programs\Python\Python310\lib\site-packages\starlette\routing.py", line 61, in app
    response = await func(request)
  File "C:\Users\tomer\AppData\Local\Programs\Python\Python310\lib\site-packages\fastapi\routing.py", line 227, in app
    raw_response = await run_endpoint_function(
  File "C:\Users\tomer\AppData\Local\Programs\Python\Python310\lib\site-packages\fastapi\routing.py", line 162, in run_endpoint_function
    return await run_in_threadpool(dependant.call, **values)
  File "C:\Users\tomer\AppData\Local\Programs\Python\Python310\lib\site-packages\starlette\concurrency.py", line 39, in run_in_threadpool
    return await anyio.to_thread.run_sync(func, *args)
  File "C:\Users\tomer\AppData\Local\Programs\Python\Python310\lib\site-packages\anyio\to_thread.py", line 28, in run_sync
    return await get_asynclib().run_sync_in_worker_thread(func, *args, cancellable=cancellable,
  File "C:\Users\tomer\AppData\Local\Programs\Python\Python310\lib\site-packages\anyio\_backends\_asyncio.py", line 818, in run_sync_in_worker_thread
    return await future
  File "C:\Users\tomer\AppData\Local\Programs\Python\Python310\lib\site-packages\anyio\_backends\_asyncio.py", line 754, in run
    result = context.run(func, *args)
  File "C:\Users\tomer\Desktop\sadna\Workshop\.\Code\Backend\Server-FastAPI\Server.py", line 153, in register
    res = service.register(user_info.id, user_info_dict)
  File "C:\Users\tomer\Desktop\sadna\Workshop\.\Code\Backend\Service\Service.py", line 137, in register
    response = Response(self.facade.register(guest_id, user_info))
  File "C:\Users\tomer\Desktop\sadna\Workshop\.\Code\Backend\Domain\Facade.py", line 103, in register
    return self.user_controller.register(guest_id, user_info)
  File "C:\Users\tomer\Desktop\sadna\Workshop\.\Code\Backend\Domain\Controllers\UserController.py", line 42, in register
    new_member = self.__users[user_id].register(member_info)
KeyError: '2'
ERROR:uvicorn.error:Exception in ASGI application
Traceback (most recent call last):
  File "C:\Users\tomer\AppData\Local\Programs\Python\Python310\lib\site-packages\uvicorn\protocols\http\httptools_impl.py", line 372, in run_asgi
    result = await app(self.scope, self.receive, self.send)
  File "C:\Users\tomer\AppData\Local\Programs\Python\Python310\lib\site-packages\uvicorn\middleware\proxy_headers.py", line 75, in __call__
    return await self.app(scope, receive, send)
  File "C:\Users\tomer\AppData\Local\Programs\Python\Python310\lib\site-packages\fastapi\applications.py", line 261, in __call__
    await super().__call__(scope, receive, send)
  File "C:\Users\tomer\AppData\Local\Programs\Python\Python310\lib\site-packages\starlette\applications.py", line 112, in __call__
    await self.middleware_stack(scope, receive, send)
  File "C:\Users\tomer\AppData\Local\Programs\Python\Python310\lib\site-packages\starlette\middleware\errors.py", line 181, in __call__
    raise exc
  File "C:\Users\tomer\AppData\Local\Programs\Python\Python310\lib\site-packages\starlette\middleware\errors.py", line 159, in __call__
    await self.app(scope, receive, _send)
  File "C:\Users\tomer\AppData\Local\Programs\Python\Python310\lib\site-packages\starlette\middleware\cors.py", line 92, in __call__
    await self.simple_response(scope, receive, send, request_headers=headers)
  File "C:\Users\tomer\AppData\Local\Programs\Python\Python310\lib\site-packages\starlette\middleware\cors.py", line 147, in simple_response
    await self.app(scope, receive, send)
  File "C:\Users\tomer\AppData\Local\Programs\Python\Python310\lib\site-packages\starlette\exceptions.py", line 82, in __call__
    raise exc
  File "C:\Users\tomer\AppData\Local\Programs\Python\Python310\lib\site-packages\starlette\exceptions.py", line 71, in __call__
    await self.app(scope, receive, sender)
  File "C:\Users\tomer\AppData\Local\Programs\Python\Python310\lib\site-packages\fastapi\middleware\asyncexitstack.py", line 21, in __call__
    raise e
  File "C:\Users\tomer\AppData\Local\Programs\Python\Python310\lib\site-packages\fastapi\middleware\asyncexitstack.py", line 18, in __call__
    await self.app(scope, receive, send)
  File "C:\Users\tomer\AppData\Local\Programs\Python\Python310\lib\site-packages\starlette\routing.py", line 656, in __call__
    await route.handle(scope, receive, send)
  File "C:\Users\tomer\AppData\Local\Programs\Python\Python310\lib\site-packages\starlette\routing.py", line 259, in handle
    await self.app(scope, receive, send)
  File "C:\Users\tomer\AppData\Local\Programs\Python\Python310\lib\site-packages\starlette\routing.py", line 61, in app
    response = await func(request)
  File "C:\Users\tomer\AppData\Local\Programs\Python\Python310\lib\site-packages\fastapi\routing.py", line 227, in app
    raw_response = await run_endpoint_function(
  File "C:\Users\tomer\AppData\Local\Programs\Python\Python310\lib\site-packages\fastapi\routing.py", line 162, in run_endpoint_function
    return await run_in_threadpool(dependant.call, **values)
  File "C:\Users\tomer\AppData\Local\Programs\Python\Python310\lib\site-packages\starlette\concurrency.py", line 39, in run_in_threadpool
    return await anyio.to_thread.run_sync(func, *args)
  File "C:\Users\tomer\AppData\Local\Programs\Python\Python310\lib\site-packages\anyio\to_thread.py", line 28, in run_sync
    return await get_asynclib().run_sync_in_worker_thread(func, *args, cancellable=cancellable,
  File "C:\Users\tomer\AppData\Local\Programs\Python\Python310\lib\site-packages\anyio\_backends\_asyncio.py", line 818, in run_sync_in_worker_thread
    return await future
  File "C:\Users\tomer\AppData\Local\Programs\Python\Python310\lib\site-packages\anyio\_backends\_asyncio.py", line 754, in run
    result = context.run(func, *args)
  File "C:\Users\tomer\Desktop\sadna\Workshop\.\Code\Backend\Server-FastAPI\Server.py", line 153, in register
    res = service.register(user_info.id, user_info_dict)
  File "C:\Users\tomer\Desktop\sadna\Workshop\.\Code\Backend\Service\Service.py", line 137, in register
    response = Response(self.facade.register(guest_id, user_info))
  File "C:\Users\tomer\Desktop\sadna\Workshop\.\Code\Backend\Domain\Facade.py", line 103, in register
    return self.user_controller.register(guest_id, user_info)
  File "C:\Users\tomer\Desktop\sadna\Workshop\.\Code\Backend\Domain\Controllers\UserController.py", line 42, in register
    new_member = self.__users[user_id].register(member_info)
KeyError: '2'
ERROR:uvicorn.error:Exception in ASGI application
Traceback (most recent call last):
  File "C:\Users\tomer\AppData\Local\Programs\Python\Python310\lib\site-packages\uvicorn\protocols\http\httptools_impl.py", line 372, in run_asgi
    result = await app(self.scope, self.receive, self.send)
  File "C:\Users\tomer\AppData\Local\Programs\Python\Python310\lib\site-packages\uvicorn\middleware\proxy_headers.py", line 75, in __call__
    return await self.app(scope, receive, send)
  File "C:\Users\tomer\AppData\Local\Programs\Python\Python310\lib\site-packages\fastapi\applications.py", line 261, in __call__
    await super().__call__(scope, receive, send)
  File "C:\Users\tomer\AppData\Local\Programs\Python\Python310\lib\site-packages\starlette\applications.py", line 112, in __call__
    await self.middleware_stack(scope, receive, send)
  File "C:\Users\tomer\AppData\Local\Programs\Python\Python310\lib\site-packages\starlette\middleware\errors.py", line 181, in __call__
    raise exc
  File "C:\Users\tomer\AppData\Local\Programs\Python\Python310\lib\site-packages\starlette\middleware\errors.py", line 159, in __call__
    await self.app(scope, receive, _send)
  File "C:\Users\tomer\AppData\Local\Programs\Python\Python310\lib\site-packages\starlette\middleware\cors.py", line 92, in __call__
    await self.simple_response(scope, receive, send, request_headers=headers)
  File "C:\Users\tomer\AppData\Local\Programs\Python\Python310\lib\site-packages\starlette\middleware\cors.py", line 147, in simple_response
    await self.app(scope, receive, send)
  File "C:\Users\tomer\AppData\Local\Programs\Python\Python310\lib\site-packages\starlette\exceptions.py", line 82, in __call__
    raise exc
  File "C:\Users\tomer\AppData\Local\Programs\Python\Python310\lib\site-packages\starlette\exceptions.py", line 71, in __call__
    await self.app(scope, receive, sender)
  File "C:\Users\tomer\AppData\Local\Programs\Python\Python310\lib\site-packages\fastapi\middleware\asyncexitstack.py", line 21, in __call__
    raise e
  File "C:\Users\tomer\AppData\Local\Programs\Python\Python310\lib\site-packages\fastapi\middleware\asyncexitstack.py", line 18, in __call__
    await self.app(scope, receive, send)
  File "C:\Users\tomer\AppData\Local\Programs\Python\Python310\lib\site-packages\starlette\routing.py", line 656, in __call__
    await route.handle(scope, receive, send)
  File "C:\Users\tomer\AppData\Local\Programs\Python\Python310\lib\site-packages\starlette\routing.py", line 259, in handle
    await self.app(scope, receive, send)
  File "C:\Users\tomer\AppData\Local\Programs\Python\Python310\lib\site-packages\starlette\routing.py", line 61, in app
    response = await func(request)
  File "C:\Users\tomer\AppData\Local\Programs\Python\Python310\lib\site-packages\fastapi\routing.py", line 227, in app
    raw_response = await run_endpoint_function(
  File "C:\Users\tomer\AppData\Local\Programs\Python\Python310\lib\site-packages\fastapi\routing.py", line 162, in run_endpoint_function
    return await run_in_threadpool(dependant.call, **values)
  File "C:\Users\tomer\AppData\Local\Programs\Python\Python310\lib\site-packages\starlette\concurrency.py", line 39, in run_in_threadpool
    return await anyio.to_thread.run_sync(func, *args)
  File "C:\Users\tomer\AppData\Local\Programs\Python\Python310\lib\site-packages\anyio\to_thread.py", line 28, in run_sync
    return await get_asynclib().run_sync_in_worker_thread(func, *args, cancellable=cancellable,
  File "C:\Users\tomer\AppData\Local\Programs\Python\Python310\lib\site-packages\anyio\_backends\_asyncio.py", line 818, in run_sync_in_worker_thread
    return await future
  File "C:\Users\tomer\AppData\Local\Programs\Python\Python310\lib\site-packages\anyio\_backends\_asyncio.py", line 754, in run
    result = context.run(func, *args)
  File "C:\Users\tomer\Desktop\sadna\Workshop\.\Code\Backend\Server-FastAPI\Server.py", line 153, in register
    res = service.register(user_info.id, user_info_dict)
  File "C:\Users\tomer\Desktop\sadna\Workshop\.\Code\Backend\Service\Service.py", line 137, in register
    response = Response(self.facade.register(guest_id, user_info))
  File "C:\Users\tomer\Desktop\sadna\Workshop\.\Code\Backend\Domain\Facade.py", line 103, in register
    return self.user_controller.register(guest_id, user_info)
  File "C:\Users\tomer\Desktop\sadna\Workshop\.\Code\Backend\Domain\Controllers\UserController.py", line 42, in register
    new_member = self.__users[user_id].register(member_info)
KeyError: '2'
CRITICAL:root:username already exists
CRITICAL:root:invalid password
CRITICAL:root:invalid password
INFO:uvicorn.error:Started server process [17664]
INFO:uvicorn.error:Waiting for application startup.
INFO:uvicorn.error:Application startup complete.
CRITICAL:root:invalid password
CRITICAL:root:invalid password
CRITICAL:root:invalid password
INFO:uvicorn.error:Started server process [4616]
INFO:uvicorn.error:Waiting for application startup.
INFO:uvicorn.error:Application startup complete.
ERROR:uvicorn.error:Exception in ASGI application
Traceback (most recent call last):
  File "C:\Users\tomer\AppData\Local\Programs\Python\Python310\lib\site-packages\uvicorn\protocols\http\httptools_impl.py", line 372, in run_asgi
    result = await app(self.scope, self.receive, self.send)
  File "C:\Users\tomer\AppData\Local\Programs\Python\Python310\lib\site-packages\uvicorn\middleware\proxy_headers.py", line 75, in __call__
    return await self.app(scope, receive, send)
  File "C:\Users\tomer\AppData\Local\Programs\Python\Python310\lib\site-packages\fastapi\applications.py", line 261, in __call__
    await super().__call__(scope, receive, send)
  File "C:\Users\tomer\AppData\Local\Programs\Python\Python310\lib\site-packages\starlette\applications.py", line 112, in __call__
    await self.middleware_stack(scope, receive, send)
  File "C:\Users\tomer\AppData\Local\Programs\Python\Python310\lib\site-packages\starlette\middleware\errors.py", line 181, in __call__
    raise exc
  File "C:\Users\tomer\AppData\Local\Programs\Python\Python310\lib\site-packages\starlette\middleware\errors.py", line 159, in __call__
    await self.app(scope, receive, _send)
  File "C:\Users\tomer\AppData\Local\Programs\Python\Python310\lib\site-packages\starlette\middleware\cors.py", line 92, in __call__
    await self.simple_response(scope, receive, send, request_headers=headers)
  File "C:\Users\tomer\AppData\Local\Programs\Python\Python310\lib\site-packages\starlette\middleware\cors.py", line 147, in simple_response
    await self.app(scope, receive, send)
  File "C:\Users\tomer\AppData\Local\Programs\Python\Python310\lib\site-packages\starlette\exceptions.py", line 82, in __call__
    raise exc
  File "C:\Users\tomer\AppData\Local\Programs\Python\Python310\lib\site-packages\starlette\exceptions.py", line 71, in __call__
    await self.app(scope, receive, sender)
  File "C:\Users\tomer\AppData\Local\Programs\Python\Python310\lib\site-packages\fastapi\middleware\asyncexitstack.py", line 21, in __call__
    raise e
  File "C:\Users\tomer\AppData\Local\Programs\Python\Python310\lib\site-packages\fastapi\middleware\asyncexitstack.py", line 18, in __call__
    await self.app(scope, receive, send)
  File "C:\Users\tomer\AppData\Local\Programs\Python\Python310\lib\site-packages\starlette\routing.py", line 656, in __call__
    await route.handle(scope, receive, send)
  File "C:\Users\tomer\AppData\Local\Programs\Python\Python310\lib\site-packages\starlette\routing.py", line 259, in handle
    await self.app(scope, receive, send)
  File "C:\Users\tomer\AppData\Local\Programs\Python\Python310\lib\site-packages\starlette\routing.py", line 61, in app
    response = await func(request)
  File "C:\Users\tomer\AppData\Local\Programs\Python\Python310\lib\site-packages\fastapi\routing.py", line 227, in app
    raw_response = await run_endpoint_function(
  File "C:\Users\tomer\AppData\Local\Programs\Python\Python310\lib\site-packages\fastapi\routing.py", line 162, in run_endpoint_function
    return await run_in_threadpool(dependant.call, **values)
  File "C:\Users\tomer\AppData\Local\Programs\Python\Python310\lib\site-packages\starlette\concurrency.py", line 39, in run_in_threadpool
    return await anyio.to_thread.run_sync(func, *args)
  File "C:\Users\tomer\AppData\Local\Programs\Python\Python310\lib\site-packages\anyio\to_thread.py", line 28, in run_sync
    return await get_asynclib().run_sync_in_worker_thread(func, *args, cancellable=cancellable,
  File "C:\Users\tomer\AppData\Local\Programs\Python\Python310\lib\site-packages\anyio\_backends\_asyncio.py", line 818, in run_sync_in_worker_thread
    return await future
  File "C:\Users\tomer\AppData\Local\Programs\Python\Python310\lib\site-packages\anyio\_backends\_asyncio.py", line 754, in run
    result = context.run(func, *args)
  File "C:\Users\tomer\Desktop\sadna\Workshop\.\Code\Backend\Server-FastAPI\Server.py", line 177, in add_product_to_shopping_cart
    res = service.add_product_to_shopping_cart(
  File "C:\Users\tomer\Desktop\sadna\Workshop\.\Code\Backend\Service\Service.py", line 200, in add_product_to_shopping_cart
    response = Response(self.facade.add_product_to_shopping_cart(user_id, store_id, product_id, quantity))
  File "C:\Users\tomer\Desktop\sadna\Workshop\.\Code\Backend\Domain\Facade.py", line 172, in add_product_to_shopping_cart
    total_quantity = self.user_controller.get_shopping_cart(user_id). \
KeyError: '1'
CRITICAL:root:User is already an Owner of this store
CRITICAL:root:User is already an Owner of this store
INFO:uvicorn.error:Shutting down
INFO:uvicorn.error:Waiting for application shutdown.
INFO:uvicorn.error:Application shutdown complete.
INFO:uvicorn.error:Finished server process [4616]
